Add note to exception raised in ``PyErr_SetObject`` when normalization fails.
